Workbook

Sheet Dashboard
A1: Queuing Solutions — Engineering Progress Dashboard (v2)
A3: Rows in Sheet '3. Modules & Features' (incl. 5 section-header rows): | B3: 89 | C3: ← includes 5 section-header rows (M1—/M5—/M8—/M9—/M11—) which have no feature text
A4: Actual individual feature rows (ID format Mx-NN): | B4: 84
A5: Rows audited this report: | B5: =COUNTA('Module Audit'!A2:A85)
A6: Coverage of actual feature rows: | B6: =B5/B4
A7: Overall Weighted % Complete: | B7: =AVERAGE('Module Audit'!G2:G85)
A9: Test Suite Results (pytest – run 2026-08-23):
A10: Total collected | B10: 116
A11: Passed | B11: 104
A12: Failed | B12: 11
A13: Skipped | B13: 1
A14: Key failures | B14: test_rbac.py(4), test_phase1.py(2), test_phase2.py(1), test_phase4.py(1), test_company_admin.py(1), test_scenario57.py(1), test_phase7.py(1 – fakeredis missing)
A17: Status | B17: Count | C17: % of Total
A18: Fully Working | B18: =COUNTIF('Module Audit'!F2:F85,"Fully Working") | C18: =B18/84
A19: Partially Working | B19: =COUNTIF('Module Audit'!F2:F85,"Partially Working") | C19: =B19/84
A20: Scaffolded | B20: =COUNTIF('Module Audit'!F2:F85,"Scaffolded") | C20: =B20/84
A21: Broken | B21: =COUNTIF('Module Audit'!F2:F85,"Broken") | C21: =B21/84
A22: Not Started | B22: =COUNTIF('Module Audit'!F2:F85,"Not Started") | C22: =B22/84
A23: Not Applicable | B23: =COUNTIF('Module Audit'!F2:F85,"Not Applicable") | C23: =B23/84
A26: Priority | B26: Weighted % Complete | C26: Count
A27: Must | B27: =IFERROR(AVERAGEIF('Module Audit'!D2:D85,A27,'Module Audit'!G2:G85),0) | C27: =COUNTIF('Module Audit'!D2:D85,A27)
A28: Should | B28: =IFERROR(AVERAGEIF('Module Audit'!D2:D85,A28,'Module Audit'!G2:G85),0) | C28: =COUNTIF('Module Audit'!D2:D85,A28)
A29: Could | B29: =IFERROR(AVERAGEIF('Module Audit'!D2:D85,A29,'Module Audit'!G2:G85),0) | C29: =COUNTIF('Module Audit'!D2:D85,A29)
A32: Module Group | B32: Weighted % Complete | C32: Count
A33: M0 – Platform Administration | B33: =IFERROR(AVERAGEIF('Module Audit'!C2:C85,A33,'Module Audit'!G2:G85),0) | C33: =COUNTIF('Module Audit'!C2:C85,A33)
A34: M1 – Company & Multi-Branch Registration | B34: =IFERROR(AVERAGEIF('Module Audit'!C2:C85,A34,'Module Audit'!G2:G85),0) | C34: =COUNTIF('Module Audit'!C2:C85,A34)
A35: M10 – Reporting & Analytics | B35: =IFERROR(AVERAGEIF('Module Audit'!C2:C85,A35,'Module Audit'!G2:G85),0) | C35: =COUNTIF('Module Audit'!C2:C85,A35)
A36: M11 – Cross-Cutting Platform Concerns | B36: =IFERROR(AVERAGEIF('Module Audit'!C2:C85,A36,'Module Audit'!G2:G85),0) | C36: =COUNTIF('Module Audit'!C2:C85,A36)
A37: M2 – Subscription, Branch & User Assignment | B37: =IFERROR(AVERAGEIF('Module Audit'!C2:C85,A37,'Module Audit'!G2:G85),0) | C37: =COUNTIF('Module Audit'!C2:C85,A37)
A38: M3 – Company Admin Dashboard & Monitoring | B38: =IFERROR(AVERAGEIF('Module Audit'!C2:C85,A38,'Module Audit'!G2:G85),0) | C38: =COUNTIF('Module Audit'!C2:C85,A38)
A39: M4 – Branch Operator Configuration Panel | B39: =IFERROR(AVERAGEIF('Module Audit'!C2:C85,A39,'Module Audit'!G2:G85),0) | C39: =COUNTIF('Module Audit'!C2:C85,A39)
A40: M5 – Queuing Solution Methods | B40: =IFERROR(AVERAGEIF('Module Audit'!C2:C85,A40,'Module Audit'!G2:G85),0) | C40: =COUNTIF('Module Audit'!C2:C85,A40)
A41: M6 – Responsive Web Access | B41: =IFERROR(AVERAGEIF('Module Audit'!C2:C85,A41,'Module Audit'!G2:G85),0) | C41: =COUNTIF('Module Audit'!C2:C85,A41)
A42: M7 – KOT Printing | B42: =IFERROR(AVERAGEIF('Module Audit'!C2:C85,A42,'Module Audit'!G2:G85),0) | C42: =COUNTIF('Module Audit'!C2:C85,A42)
A43: M8 – Auth, RBAC & Multi-Tenancy | B43: =IFERROR(AVERAGEIF('Module Audit'!C2:C85,A43,'Module Audit'!G2:G85),0) | C43: =COUNTIF('Module Audit'!C2:C85,A43)
A44: M9 – Alerts & Notifications Engine | B44: =IFERROR(AVERAGEIF('Module Audit'!C2:C85,A44,'Module Audit'!G2:G85),0) | C44: =COUNTIF('Module Audit'!C2:C85,A44)
A47: Top Must-Priority Blockers (Worst Shape First)
A48: ID | B48: Feature | C48: Status | D48: Blocker
A49: M8-02 | B49: Password reset / forgot password | C49: Scaffolded | D49: Zero backend implementation – no reset token generation, no email dispatch, no confirm endpoint
A50: M9-02 | B50: Multi-channel delivery | C50: Scaffolded | D50: Only in_app channel works; SMS/email/WhatsApp channels go to console stdout
...

Sheet Module Audit
A1: ID | B1: Feature | C1: Module Group | D1: Priority | E1: Complexity | F1: Status | G1: % Complete | H1: Backend Evidence | I1: Frontend Evidence | J1: End-to-End Wired? | K1: Tested? | L1: Confidence | M1: Verification Method | N1: Blockers | O1: Next Step to Close Gap
A2: M0-01 | B2: Platform Super Admin console login | C2: M0 – Platform Administration | D2: Must | E2: Low | F2: Fully Working | G2: 100 | H2: accounts/views.py:CustomTokenObtainPairView + RBAC role=super_admin; POST /api/auth/login/ | I2: src/routes/login.tsx + src/routes/app.tsx (SuperAdminView gating); super-admin.tsx (1530 lines) | J2: Y | K2: Y – test_auth.py (5 pass); test_rbac.py partial | L2: High | M2: Ran pytest tests/ – test_auth.py all pass; manually confirmed login flow in prior session | N2: None | O2: —
A3: M0-02 | B3: Company onboarding & approval queue | C3: M0 – Platform Administration | D3: Must | E3: Medium | F3: Partially Working | G3: 50 | H3: companies/views.py:CompanyViewSet (approve/reject actions); POST /api/companies/register/ | I3: super-admin.tsx – companies view with approve/reject; test_phase1.py::test_company_approval_and_suspension_gating FAILED | J3: N | K3: N – test_phase1.py::test_company_approval_and_suspension_gating FAILED | L3: High | M3: Ran pytest tests/test_phase1.py – test_company_approval_and_suspension_gating FAILED (assert status active after approval returned wrong state) | N3: test_company_approval_and_suspension_gating fails – approval status logic bug | O3: Fix company approval view status transition; re-run test_phase1.py
A4: M0-03 | B4: Package/plan CRUD | C4: M0 – Platform Administration | D4: Must | E4: Medium | F4: Fully Working | G4: 100 | H4: billing/views.py:PlanComponentViewSet (IsSuperAdmin); /api/billing/plan-components/; PriceChangeLog signal on update | I4: super-admin.tsx – plan components tab with full CRUD UI | J4: Y | K4: Y – test_phase7.py covers plan components | L4: High | M4: Read code; ran pytest tests/test_phase7.py – relevant tests pass | N4: None | O4: —
A5: M0-04 | B5: Global feature flags & method toggles | C5: M0 – Platform Administration | D5: Must | E5: Medium | F5: Partially Working | G5: 50 | H5: core/models.py:PlatformSetting; companies/views.py reads registration_open flag; QueueMethod model with is_enabled toggle | I5: super-admin.tsx renders some settings; no dedicated PlatformSettings CRUD endpoint registered in urls.py | J5: N | K5: N | L5: High | M5: Searched urls.py exhaustively – no /api/platform-settings/ route exists; code reads settings but no admin CRUD endpoint | N5: No /api/platform-settings/ endpoint; feature flag CRUD not wired to admin UI | O5: Register PlatformSetting ViewSet in urls.py and wire to super-admin flags tab
A6: M0-05 | B6: Platform-wide analytics | C6: M0 – Platform Administration | D6: Should | E6: Medium | F6: Partially Working | G6: 50 | H6: analytics/views.py:ReportTrendsView (super_admin role returns all snapshots) | I6: super-admin.tsx – dashboard shows MRR and total waiting (locally computed from state.companies/branches, not a dedicated API aggregate) | J6: N | K6: N | L6: High | M6: Read super-admin.tsx:19-21 – MRR = reduce over state.companies.monthlySpend (client-side only); no /api/platform/stats endpoint | N6: Platform KPIs (MRR, ARR) are computed client-side from already-loaded company list – not a real aggregate | O6: Add GET /api/platform/stats/ view for server-side KPI aggregation
A7: M0-06 | B7: Upgrade/add-on request workflow | C7: M0 – Platform Administration | D7: Must | E7: Medium | F7: Fully Working | G7: 100 | H7: billing/models.py:UpgradeRequest; billing/views.py:UpgradeRequestViewSet; /api/upgrades/ | I7: super-admin.tsx – upgrade requests view; company-admin.tsx – upgrade CTA | J7: Y | K7: N | L7: High | M7: Read code; endpoints confirmed in urls.py; UI confirmed in super-admin.tsx | N7: None | O7: Add test_upgrade_request.py
A8: M0-07 | B8: Global notification templates | C8: M0 – Platform Administration | D8: Should | E8: Low | F8: Fully Working | G8: 100 | H8: notifications/views.py:NotificationTemplateViewSet; /api/notification-templates/ | I8: N/A – no dedicated template editor UI for super admin found | J8: Y | K8: N | L8: High | M8: Read code; endpoint confirmed in urls.py and router | N8: Super admin UI for template editing not implemented in frontend | O8: Add NotificationTemplate editor tab to super-admin.tsx
A9: M0-08 | B9: Platform support/impersonation tools | C9: M0 – Platform Administration | D9: Could | E9: Medium | F9: Not Started | G9: 0 | H9: N/A – searched all views.py for 'impersonat|switch_user|support_tool' – zero hits | I9: N/A | J9: N | K9: N | L9: High | M9: grep across entire backend directory for impersonat|SwitchUser|support_tool – no results | N9: Feature entirely absent | O9: Implement if required (could use django-hijack or custom JWT impersonation)
A10: M1-01 | B10: Company self sign-up wizard | C10: M1 – Company & Multi-Branch Registration | D10: Must | E10: Medium | F10: Partially Working | G10: 50 | H10: companies/views.py:CompanyRegistrationView; POST /api/companies/register/ | I10: src/routes/signup.tsx (42 KB multi-step wizard) | J10: N | K10: N – test_phase1.py::test_company_registration_validation FAILED | L10: High | M10: Ran pytest tests/test_phase1.py – test_company_registration_validation FAILED (assert 400 but got different status) | N10: Registration validation test fails; CAPTCHA is MOCK_CAPTCHA_TOKEN (src/routes/$companySlug.tsx:187) | O10: Fix validation logic in CompanyRegistrationView; integrate real CAPTCHA
A11: M1-02 | B11: Company profile & branding | C11: M1 – Company & Multi-Branch Registration | D11: Must | E11: Low | F11: Partially Working | G11: 50 | H11: companies/models.py:Company (logo_url, brand_colors JSONField); CompanyViewSet partial_update | I11: company-admin.tsx – settings/branding tab; signup.tsx branding step | J11: Y | K11: N | L11: High | M11: Read companies/models.py – logo_url and brand_colors fields exist; no S3 storage configured (default_storage is local) | N11: Assets stored locally, not S3 – not production-ready; no AWS_S3 credentials | O11: Configure AWS S3/Cloudflare R2 storage backend in settings.py
A12: M1-03 | B12: Branch creation & management | C12: M1 – Company & Multi-Branch Registration | D12: Must | E12: Medium | F12: Fully Working | G12: 100 | H12: branches/views.py:BranchViewSet; /api/branches/; Branch.operating_hours JSONField | I12: company-admin.tsx – branches tab with create/edit/archive | J12: Y | K12: Y – test_phase1.py passes | L12: High | M12: Ran pytest tests/test_phase1.py; branches tests pass; read models.py | N12: None | O12: —
A13: M1-04 | B13: Branch-level package override | C13: M1 – Company & Multi-Branch Registration | D13: Should | E13: Medium | F13: Fully Working | G13: 100 | H13: billing/models.py:CompanyPlanAllocation (branch FK – per-branch allocation); /api/billing/allocations/ | I13: billing-plan-configurator.tsx – branch-level component allocation | J13: Y | K13: Y – test_phase7.py covers allocations | L13: High | M13: Read billing/models.py:56 – CompanyPlanAllocation has nullable branch FK enabling per-branch overrides | N13: None | O13: —
... A85: M11-10 | B85: Backup & disaster recovery | C85: M11 – Cross-Cutting Platform Concerns | D85: Must | E85: Medium | F85: Partially Working | G85: 50 | H85: core/backup.py:run_mysql_backup(); core/tasks.py:purge_expired_customer_pii(); CELERY_BEAT_SCHEDULE entries | I85: N/A | J85: N | K85: Y – test_phase7.py covers PII purge; backup file creation not tested | L85: High | M85: Read core/backup.py – calls mysqldump subprocess; Celery beat schedules confirmed in settings.py; purge_expired_customer_pii passes in test_phase7.py; mysqldump must be on PATH | N85: Celery beat must be running; mysqldump must be on PATH (XAMPP installs it in MySQL bin); no DR runbook | O85: Confirm mysqldump in PATH; start Celery beat; create DR runbook

Sheet Untracked - Extra Code
A1: Path / Location | B1: Description | C1: Risk
A2: completed_modules.xlsx (root + public/) | B2: Separate UI polish tracker (MOD-01…MOD-10) for frontend visual improvements; not in main breakdown sheet | C2: Low
A3: src/components/site/scroll-controlled-background.tsx | B3: Scroll-linked background video – frontend-only visual enhancement; not in any M0-M11 module | C3: Low
A4: backend/tests/locustfile.py | B4: Locust load-test script (~200 lines); not in breakdown spec but useful for NFR testing | C4: Low
A5: backend/tests/test_scenario57.py | B5: Specific scenario test (named 'scenario57'); 1 test FAILS – negative qualification removal edge case | C5: Medium – failing test
A6: backend/tests/test_phase6.py | B6: Phase 6 test file (6 KB); covers security/compliance tests not in M0-M11 breakdown | C6: Low
A7: backend/tests/test_phase7.py | B7: Phase 7 test file (36 KB – largest); covers data retention, backup, WebSocket Redis – beyond main spec | C7: Low
A8: billing/stripe_helper.py | B8: Stripe wrapper module (3 KB); not listed as standalone module in breakdown | C8: Low
A9: core/honeypot.py | B9: Bot honeypot field validator – security extra beyond spec items | C9: Low
A10: core/throttles.py | B10: Custom DRF throttle classes – referenced in spec (M11-04) but implemented as standalone module | C10: Low
A11: core/crypto.py | B11: Blind-index + tracking-code generator – PII encryption support beyond explicit spec | C11: Low
A12: backend/subscriptions/ | B12: Empty subscriptions/ app (only services/ subdir); functionality consolidated into billing/ | C12: Low – no routes
... A17: backend/display/ | B17: display/ Django app exists with DisplayDevice model but zero views/routes – dead app stub beyond display board | C17: High – empty app causes confusion
